Traceback (most recent call last):
  File "/home/maciej/anaconda3/lib/python3.12/site-packages/jupyter_cache/executors/utils.py", line 58, in single_nb_execution
    executenb(
  File "/home/maciej/anaconda3/lib/python3.12/site-packages/nbclient/client.py", line 1305, in execute
    return NotebookClient(nb=nb, resources=resources, km=km, **kwargs).execute()
           ^^^^^^^^^^^^^^^^^^^^^^^^^^^^^^^^^^^^^^^^^^^^^^^^^^^^^^^^^^^^^^^^^^^^^
  File "/home/maciej/anaconda3/lib/python3.12/site-packages/jupyter_core/utils/__init__.py", line 165, in wrapped
    return loop.run_until_complete(inner)
           ^^^^^^^^^^^^^^^^^^^^^^^^^^^^^^
  File "/home/maciej/anaconda3/lib/python3.12/asyncio/base_events.py", line 685, in run_until_complete
    return future.result()
           ^^^^^^^^^^^^^^^
  File "/home/maciej/anaconda3/lib/python3.12/site-packages/nbclient/client.py", line 705, in async_execute
    await self.async_execute_cell(
  File "/home/maciej/anaconda3/lib/python3.12/site-packages/nbclient/client.py", line 1058, in async_execute_cell
    await self._check_raise_for_error(cell, cell_index, exec_reply)
  File "/home/maciej/anaconda3/lib/python3.12/site-packages/nbclient/client.py", line 914, in _check_raise_for_error
    raise CellExecutionError.from_cell_and_msg(cell, exec_reply_content)
nbclient.exceptions.CellExecutionError: An error occurred while executing the following cell:
------------------
import tensorflow as tf
from tensorflow.keras.models import Sequential
from tensorflow.keras.layers import Dense
from tensorflow.keras.datasets import boston_housing
from sklearn.model_selection import train_test_split
from sklearn.preprocessing import StandardScaler

# Wczytanie danych
(x_train, y_train), (x_test, y_test) = boston_housing.load_data()

# Normalizacja danych
scaler = StandardScaler()
x_train = scaler.fit_transform(x_train)
x_test = scaler.transform(x_test)

# Budowa modelu
model = Sequential([
    Dense(64, activation='relu', input_shape=(x_train.shape[1],)),
    Dense(64, activation='relu'),
    Dense(1)
])

# Kompilacja modelu
model.compile(optimizer='adam', loss='mse', metrics=['mae'])

# Trenowanie modelu
model.fit(x_train, y_train, epochs=100, batch_size=10, validation_split=0.2)

# Ocena modelu
loss, mae_neural_network = model.evaluate(x_test, y_test)
print(f'Åšredni bÅ‚Ä…d bezwzglÄ™dny: {mae_neural_network}')

------------------


[0;31m---------------------------------------------------------------------------[0m
[0;31mModuleNotFoundError[0m                       Traceback (most recent call last)
Cell [0;32mIn[1], line 1[0m
[0;32m----> 1[0m [38;5;28;01mimport[39;00m [38;5;21;01mtensorflow[39;00m [38;5;28;01mas[39;00m [38;5;21;01mtf[39;00m
[1;32m      2[0m [38;5;28;01mfrom[39;00m [38;5;21;01mtensorflow[39;00m[38;5;21;01m.[39;00m[38;5;21;01mkeras[39;00m[38;5;21;01m.[39;00m[38;5;21;01mmodels[39;00m [38;5;28;01mimport[39;00m Sequential
[1;32m      3[0m [38;5;28;01mfrom[39;00m [38;5;21;01mtensorflow[39;00m[38;5;21;01m.[39;00m[38;5;21;01mkeras[39;00m[38;5;21;01m.[39;00m[38;5;21;01mlayers[39;00m [38;5;28;01mimport[39;00m Dense

[0;31mModuleNotFoundError[0m: No module named 'tensorflow'

