Traceback (most recent call last):
  File "/home/maciej/anaconda3/lib/python3.12/site-packages/jupyter_cache/executors/utils.py", line 58, in single_nb_execution
    executenb(
  File "/home/maciej/anaconda3/lib/python3.12/site-packages/nbclient/client.py", line 1305, in execute
    return NotebookClient(nb=nb, resources=resources, km=km, **kwargs).execute()
           ^^^^^^^^^^^^^^^^^^^^^^^^^^^^^^^^^^^^^^^^^^^^^^^^^^^^^^^^^^^^^^^^^^^^^
  File "/home/maciej/anaconda3/lib/python3.12/site-packages/jupyter_core/utils/__init__.py", line 165, in wrapped
    return loop.run_until_complete(inner)
           ^^^^^^^^^^^^^^^^^^^^^^^^^^^^^^
  File "/home/maciej/anaconda3/lib/python3.12/asyncio/base_events.py", line 685, in run_until_complete
    return future.result()
           ^^^^^^^^^^^^^^^
  File "/home/maciej/anaconda3/lib/python3.12/site-packages/nbclient/client.py", line 705, in async_execute
    await self.async_execute_cell(
  File "/home/maciej/anaconda3/lib/python3.12/site-packages/nbclient/client.py", line 1058, in async_execute_cell
    await self._check_raise_for_error(cell, cell_index, exec_reply)
  File "/home/maciej/anaconda3/lib/python3.12/site-packages/nbclient/client.py", line 914, in _check_raise_for_error
    raise CellExecutionError.from_cell_and_msg(cell, exec_reply_content)
nbclient.exceptions.CellExecutionError: An error occurred while executing the following cell:
------------------
# Przyk≈Çad

import tensorflow as tf

# Za≈Çadowanie zbioru danych MNIST
(x_train, y_train), (x_test, y_test) = tf.keras.datasets.mnist.load_data()

# Wstƒôpne przetwarzanie danych
x_train = x_train.astype('float32') / 255.0
x_test = x_test.astype('float32') / 255.0
y_train = tf.keras.utils.to_categorical(y_train, num_classes=10)
y_test = tf.keras.utils.to_categorical(y_test, num_classes=10)

# Definicja modelu
model = tf.keras.models.Sequential([
  tf.keras.layers.Conv2D(32, (3, 3), activation='relu', input_shape=(28, 28, 1)),
  tf.keras.layers.MaxPooling2D((2, 2)),
  tf.keras.layers.Conv2D(64, (3, 3), activation='relu'),
  tf.keras.layers.MaxPooling2D((2, 2)),
  tf.keras.layers.Flatten(),
  tf.keras.layers.Dense(10, activation='softmax')
])

# Kompilacja modelu
model.compile(optimizer='adam',
              loss='categorical_crossentropy',
              metrics=['accuracy'])

# Trenowanie modelu
model.fit(x_train.reshape(-1, 28, 28, 1), y_train, epochs=5)

# Ewaluacja modelu
loss, accuracy = model.evaluate(x_test.reshape(-1, 28, 28, 1), y_test)
print('Dok≈Çadno≈õƒá:', accuracy)
------------------


[0;31m---------------------------------------------------------------------------[0m
[0;31mModuleNotFoundError[0m                       Traceback (most recent call last)
Cell [0;32mIn[1], line 3[0m
[1;32m      1[0m [38;5;66;03m# Przyk≈Çad[39;00m
[0;32m----> 3[0m [38;5;28;01mimport[39;00m [38;5;21;01mtensorflow[39;00m [38;5;28;01mas[39;00m [38;5;21;01mtf[39;00m
[1;32m      5[0m [38;5;66;03m# Za≈Çadowanie zbioru danych MNIST[39;00m
[1;32m      6[0m (x_train, y_train), (x_test, y_test) [38;5;241m=[39m tf[38;5;241m.[39mkeras[38;5;241m.[39mdatasets[38;5;241m.[39mmnist[38;5;241m.[39mload_data()

[0;31mModuleNotFoundError[0m: No module named 'tensorflow'

