Traceback (most recent call last):
  File "/home/maciej/anaconda3/lib/python3.12/site-packages/jupyter_cache/executors/utils.py", line 58, in single_nb_execution
    executenb(
  File "/home/maciej/anaconda3/lib/python3.12/site-packages/nbclient/client.py", line 1305, in execute
    return NotebookClient(nb=nb, resources=resources, km=km, **kwargs).execute()
           ^^^^^^^^^^^^^^^^^^^^^^^^^^^^^^^^^^^^^^^^^^^^^^^^^^^^^^^^^^^^^^^^^^^^^
  File "/home/maciej/anaconda3/lib/python3.12/site-packages/jupyter_core/utils/__init__.py", line 165, in wrapped
    return loop.run_until_complete(inner)
           ^^^^^^^^^^^^^^^^^^^^^^^^^^^^^^
  File "/home/maciej/anaconda3/lib/python3.12/asyncio/base_events.py", line 685, in run_until_complete
    return future.result()
           ^^^^^^^^^^^^^^^
  File "/home/maciej/anaconda3/lib/python3.12/site-packages/nbclient/client.py", line 705, in async_execute
    await self.async_execute_cell(
  File "/home/maciej/anaconda3/lib/python3.12/site-packages/nbclient/client.py", line 1058, in async_execute_cell
    await self._check_raise_for_error(cell, cell_index, exec_reply)
  File "/home/maciej/anaconda3/lib/python3.12/site-packages/nbclient/client.py", line 914, in _check_raise_for_error
    raise CellExecutionError.from_cell_and_msg(cell, exec_reply_content)
nbclient.exceptions.CellExecutionError: An error occurred while executing the following cell:
------------------
# Przykład

import numpy as np
import pandas as pd
import tensorflow as tf
from tensorflow.keras.models import Sequential
from tensorflow.keras.layers import SimpleRNN, Dense
import matplotlib.pyplot as plt

# Pobranie danych
url = "https://raw.githubusercontent.com/jbrownlee/Datasets/master/daily-min-temperatures.csv"
data = pd.read_csv(url, parse_dates=['Date'], index_col='Date')

# Przygotowanie danych
series = data['Temp'].values
time = np.arange(len(series))

# Tworzenie sekwencji
def create_sequences(series, window_size):
    X, y = [], []
    for i in range(len(series) - window_size):
        X.append(series[i:i+window_size])
        y.append(series[i+window_size])
    return np.array(X), np.array(y)

window_size = 30
X, y = create_sequences(series, window_size)
X = X.reshape((X.shape[0], X.shape[1], 1))  # Reshape dla RNN

# Podział na zbiór treningowy i testowy
split_time = 2500
X_train, X_test = X[:split_time], X[split_time:]
y_train, y_test = y[:split_time], y[split_time:]

# Budowa modelu RNN
model = Sequential([
    SimpleRNN(50, activation='relu', input_shape=(window_size, 1)),
    Dense(1)
])

model.compile(optimizer='adam', loss='mse')
model.summary()

# Trenowanie modelu
history = model.fit(X_train, y_train, epochs=20, validation_data=(X_test, y_test))

# Prognozowanie
y_pred = model.predict(X_test)

# Wizualizacja wyników
plt.figure(figsize=(10, 6))
plt.plot(y_test, label='Rzeczywiste wartości')
plt.plot(y_pred, label='Prognozy')
plt.legend()
plt.show()
------------------

----- stderr -----

A module that was compiled using NumPy 1.x cannot be run in
NumPy 2.2.6 as it may crash. To support both 1.x and 2.x
versions of NumPy, modules must be compiled with NumPy 2.0.
Some module may need to rebuild instead e.g. with 'pybind11>=2.12'.

If you are a user of the module, the easiest solution will be to
downgrade to 'numpy<2' or try to upgrade the affected module.
We expect that some modules will need time to support NumPy 2.

Traceback (most recent call last):  File "<frozen runpy>", line 198, in _run_module_as_main
  File "<frozen runpy>", line 88, in _run_code
  File "/home/maciej/anaconda3/lib/python3.12/site-packages/ipykernel_launcher.py", line 17, in <module>
    app.launch_new_instance()
  File "/home/maciej/anaconda3/lib/python3.12/site-packages/traitlets/config/application.py", line 1075, in launch_instance
    app.start()
  File "/home/maciej/anaconda3/lib/python3.12/site-packages/ipykernel/kernelapp.py", line 701, in start
    self.io_loop.start()
  File "/home/maciej/anaconda3/lib/python3.12/site-packages/tornado/platform/asyncio.py", line 205, in start
    self.asyncio_loop.run_forever()
  File "/home/maciej/anaconda3/lib/python3.12/asyncio/base_events.py", line 639, in run_forever
    self._run_once()
  File "/home/maciej/anaconda3/lib/python3.12/asyncio/base_events.py", line 1985, in _run_once
    handle._run()
  File "/home/maciej/anaconda3/lib/python3.12/asyncio/events.py", line 88, in _run
    self._context.run(self._callback, *self._args)
  File "/home/maciej/anaconda3/lib/python3.12/site-packages/ipykernel/kernelbase.py", line 534, in dispatch_queue
    await self.process_one()
  File "/home/maciej/anaconda3/lib/python3.12/site-packages/ipykernel/kernelbase.py", line 523, in process_one
    await dispatch(*args)
  File "/home/maciej/anaconda3/lib/python3.12/site-packages/ipykernel/kernelbase.py", line 429, in dispatch_shell
    await result
  File "/home/maciej/anaconda3/lib/python3.12/site-packages/ipykernel/kernelbase.py", line 767, in execute_request
    reply_content = await reply_content
  File "/home/maciej/anaconda3/lib/python3.12/site-packages/ipykernel/ipkernel.py", line 429, in do_execute
    res = shell.run_cell(
  File "/home/maciej/anaconda3/lib/python3.12/site-packages/ipykernel/zmqshell.py", line 549, in run_cell
    return super().run_cell(*args, **kwargs)
  File "/home/maciej/anaconda3/lib/python3.12/site-packages/IPython/core/interactiveshell.py", line 3075, in run_cell
    result = self._run_cell(
  File "/home/maciej/anaconda3/lib/python3.12/site-packages/IPython/core/interactiveshell.py", line 3130, in _run_cell
    result = runner(coro)
  File "/home/maciej/anaconda3/lib/python3.12/site-packages/IPython/core/async_helpers.py", line 128, in _pseudo_sync_runner
    coro.send(None)
  File "/home/maciej/anaconda3/lib/python3.12/site-packages/IPython/core/interactiveshell.py", line 3334, in run_cell_async
    has_raised = await self.run_ast_nodes(code_ast.body, cell_name,
  File "/home/maciej/anaconda3/lib/python3.12/site-packages/IPython/core/interactiveshell.py", line 3517, in run_ast_nodes
    if await self.run_code(code, result, async_=asy):
  File "/home/maciej/anaconda3/lib/python3.12/site-packages/IPython/core/interactiveshell.py", line 3577, in run_code
    exec(code_obj, self.user_global_ns, self.user_ns)
  File "/tmp/ipykernel_15406/4255111116.py", line 4, in <module>
    import pandas as pd
  File "/home/maciej/anaconda3/lib/python3.12/site-packages/pandas/__init__.py", line 26, in <module>
    from pandas.compat import (
  File "/home/maciej/anaconda3/lib/python3.12/site-packages/pandas/compat/__init__.py", line 29, in <module>
    from pandas.compat.pyarrow import (
  File "/home/maciej/anaconda3/lib/python3.12/site-packages/pandas/compat/pyarrow.py", line 8, in <module>
    import pyarrow as pa
  File "/home/maciej/anaconda3/lib/python3.12/site-packages/pyarrow/__init__.py", line 65, in <module>
    import pyarrow.lib as _lib
----- stderr -----

A module that was compiled using NumPy 1.x cannot be run in
NumPy 2.2.6 as it may crash. To support both 1.x and 2.x
versions of NumPy, modules must be compiled with NumPy 2.0.
Some module may need to rebuild instead e.g. with 'pybind11>=2.12'.

If you are a user of the module, the easiest solution will be to
downgrade to 'numpy<2' or try to upgrade the affected module.
We expect that some modules will need time to support NumPy 2.

Traceback (most recent call last):  File "<frozen runpy>", line 198, in _run_module_as_main
  File "<frozen runpy>", line 88, in _run_code
  File "/home/maciej/anaconda3/lib/python3.12/site-packages/ipykernel_launcher.py", line 17, in <module>
    app.launch_new_instance()
  File "/home/maciej/anaconda3/lib/python3.12/site-packages/traitlets/config/application.py", line 1075, in launch_instance
    app.start()
  File "/home/maciej/anaconda3/lib/python3.12/site-packages/ipykernel/kernelapp.py", line 701, in start
    self.io_loop.start()
  File "/home/maciej/anaconda3/lib/python3.12/site-packages/tornado/platform/asyncio.py", line 205, in start
    self.asyncio_loop.run_forever()
  File "/home/maciej/anaconda3/lib/python3.12/asyncio/base_events.py", line 639, in run_forever
    self._run_once()
  File "/home/maciej/anaconda3/lib/python3.12/asyncio/base_events.py", line 1985, in _run_once
    handle._run()
  File "/home/maciej/anaconda3/lib/python3.12/asyncio/events.py", line 88, in _run
    self._context.run(self._callback, *self._args)
  File "/home/maciej/anaconda3/lib/python3.12/site-packages/ipykernel/kernelbase.py", line 534, in dispatch_queue
    await self.process_one()
  File "/home/maciej/anaconda3/lib/python3.12/site-packages/ipykernel/kernelbase.py", line 523, in process_one
    await dispatch(*args)
  File "/home/maciej/anaconda3/lib/python3.12/site-packages/ipykernel/kernelbase.py", line 429, in dispatch_shell
    await result
  File "/home/maciej/anaconda3/lib/python3.12/site-packages/ipykernel/kernelbase.py", line 767, in execute_request
    reply_content = await reply_content
  File "/home/maciej/anaconda3/lib/python3.12/site-packages/ipykernel/ipkernel.py", line 429, in do_execute
    res = shell.run_cell(
  File "/home/maciej/anaconda3/lib/python3.12/site-packages/ipykernel/zmqshell.py", line 549, in run_cell
    return super().run_cell(*args, **kwargs)
  File "/home/maciej/anaconda3/lib/python3.12/site-packages/IPython/core/interactiveshell.py", line 3075, in run_cell
    result = self._run_cell(
  File "/home/maciej/anaconda3/lib/python3.12/site-packages/IPython/core/interactiveshell.py", line 3130, in _run_cell
    result = runner(coro)
  File "/home/maciej/anaconda3/lib/python3.12/site-packages/IPython/core/async_helpers.py", line 128, in _pseudo_sync_runner
    coro.send(None)
  File "/home/maciej/anaconda3/lib/python3.12/site-packages/IPython/core/interactiveshell.py", line 3334, in run_cell_async
    has_raised = await self.run_ast_nodes(code_ast.body, cell_name,
  File "/home/maciej/anaconda3/lib/python3.12/site-packages/IPython/core/interactiveshell.py", line 3517, in run_ast_nodes
    if await self.run_code(code, result, async_=asy):
  File "/home/maciej/anaconda3/lib/python3.12/site-packages/IPython/core/interactiveshell.py", line 3577, in run_code
    exec(code_obj, self.user_global_ns, self.user_ns)
  File "/tmp/ipykernel_15406/4255111116.py", line 4, in <module>
    import pandas as pd
  File "/home/maciej/anaconda3/lib/python3.12/site-packages/pandas/__init__.py", line 49, in <module>
    from pandas.core.api import (
  File "/home/maciej/anaconda3/lib/python3.12/site-packages/pandas/core/api.py", line 9, in <module>
    from pandas.core.dtypes.dtypes import (
  File "/home/maciej/anaconda3/lib/python3.12/site-packages/pandas/core/dtypes/dtypes.py", line 24, in <module>
    from pandas._libs import (
  File "/home/maciej/anaconda3/lib/python3.12/site-packages/pyarrow/__init__.py", line 65, in <module>
    import pyarrow.lib as _lib
----- stderr -----

A module that was compiled using NumPy 1.x cannot be run in
NumPy 2.2.6 as it may crash. To support both 1.x and 2.x
versions of NumPy, modules must be compiled with NumPy 2.0.
Some module may need to rebuild instead e.g. with 'pybind11>=2.12'.

If you are a user of the module, the easiest solution will be to
downgrade to 'numpy<2' or try to upgrade the affected module.
We expect that some modules will need time to support NumPy 2.

Traceback (most recent call last):  File "<frozen runpy>", line 198, in _run_module_as_main
  File "<frozen runpy>", line 88, in _run_code
  File "/home/maciej/anaconda3/lib/python3.12/site-packages/ipykernel_launcher.py", line 17, in <module>
    app.launch_new_instance()
  File "/home/maciej/anaconda3/lib/python3.12/site-packages/traitlets/config/application.py", line 1075, in launch_instance
    app.start()
  File "/home/maciej/anaconda3/lib/python3.12/site-packages/ipykernel/kernelapp.py", line 701, in start
    self.io_loop.start()
  File "/home/maciej/anaconda3/lib/python3.12/site-packages/tornado/platform/asyncio.py", line 205, in start
    self.asyncio_loop.run_forever()
  File "/home/maciej/anaconda3/lib/python3.12/asyncio/base_events.py", line 639, in run_forever
    self._run_once()
  File "/home/maciej/anaconda3/lib/python3.12/asyncio/base_events.py", line 1985, in _run_once
    handle._run()
  File "/home/maciej/anaconda3/lib/python3.12/asyncio/events.py", line 88, in _run
    self._context.run(self._callback, *self._args)
  File "/home/maciej/anaconda3/lib/python3.12/site-packages/ipykernel/kernelbase.py", line 534, in dispatch_queue
    await self.process_one()
  File "/home/maciej/anaconda3/lib/python3.12/site-packages/ipykernel/kernelbase.py", line 523, in process_one
    await dispatch(*args)
  File "/home/maciej/anaconda3/lib/python3.12/site-packages/ipykernel/kernelbase.py", line 429, in dispatch_shell
    await result
  File "/home/maciej/anaconda3/lib/python3.12/site-packages/ipykernel/kernelbase.py", line 767, in execute_request
    reply_content = await reply_content
  File "/home/maciej/anaconda3/lib/python3.12/site-packages/ipykernel/ipkernel.py", line 429, in do_execute
    res = shell.run_cell(
  File "/home/maciej/anaconda3/lib/python3.12/site-packages/ipykernel/zmqshell.py", line 549, in run_cell
    return super().run_cell(*args, **kwargs)
  File "/home/maciej/anaconda3/lib/python3.12/site-packages/IPython/core/interactiveshell.py", line 3075, in run_cell
    result = self._run_cell(
  File "/home/maciej/anaconda3/lib/python3.12/site-packages/IPython/core/interactiveshell.py", line 3130, in _run_cell
    result = runner(coro)
  File "/home/maciej/anaconda3/lib/python3.12/site-packages/IPython/core/async_helpers.py", line 128, in _pseudo_sync_runner
    coro.send(None)
  File "/home/maciej/anaconda3/lib/python3.12/site-packages/IPython/core/interactiveshell.py", line 3334, in run_cell_async
    has_raised = await self.run_ast_nodes(code_ast.body, cell_name,
  File "/home/maciej/anaconda3/lib/python3.12/site-packages/IPython/core/interactiveshell.py", line 3517, in run_ast_nodes
    if await self.run_code(code, result, async_=asy):
  File "/home/maciej/anaconda3/lib/python3.12/site-packages/IPython/core/interactiveshell.py", line 3577, in run_code
    exec(code_obj, self.user_global_ns, self.user_ns)
  File "/tmp/ipykernel_15406/4255111116.py", line 4, in <module>
    import pandas as pd
  File "/home/maciej/anaconda3/lib/python3.12/site-packages/pandas/__init__.py", line 49, in <module>
    from pandas.core.api import (
  File "/home/maciej/anaconda3/lib/python3.12/site-packages/pandas/core/api.py", line 28, in <module>
    from pandas.core.arrays import Categorical
  File "/home/maciej/anaconda3/lib/python3.12/site-packages/pandas/core/arrays/__init__.py", line 1, in <module>
    from pandas.core.arrays.arrow import ArrowExtensionArray
  File "/home/maciej/anaconda3/lib/python3.12/site-packages/pandas/core/arrays/arrow/__init__.py", line 5, in <module>
    from pandas.core.arrays.arrow.array import ArrowExtensionArray
  File "/home/maciej/anaconda3/lib/python3.12/site-packages/pandas/core/arrays/arrow/array.py", line 53, in <module>
    from pandas.core import (
  File "/home/maciej/anaconda3/lib/python3.12/site-packages/pandas/core/ops/__init__.py", line 8, in <module>
    from pandas.core.ops.array_ops import (
  File "/home/maciej/anaconda3/lib/python3.12/site-packages/pandas/core/ops/array_ops.py", line 56, in <module>
    from pandas.core.computation import expressions
  File "/home/maciej/anaconda3/lib/python3.12/site-packages/pandas/core/computation/expressions.py", line 21, in <module>
    from pandas.core.computation.check import NUMEXPR_INSTALLED
  File "/home/maciej/anaconda3/lib/python3.12/site-packages/pandas/core/computation/check.py", line 5, in <module>
    ne = import_optional_dependency("numexpr", errors="warn")
  File "/home/maciej/anaconda3/lib/python3.12/site-packages/pandas/compat/_optional.py", line 135, in import_optional_dependency
    module = importlib.import_module(name)
  File "/home/maciej/anaconda3/lib/python3.12/importlib/__init__.py", line 90, in import_module
    return _bootstrap._gcd_import(name[level:], package, level)
  File "/home/maciej/anaconda3/lib/python3.12/site-packages/numexpr/__init__.py", line 24, in <module>
    from numexpr.interpreter import MAX_THREADS, use_vml, __BLOCK_SIZE1__
----- stderr -----

A module that was compiled using NumPy 1.x cannot be run in
NumPy 2.2.6 as it may crash. To support both 1.x and 2.x
versions of NumPy, modules must be compiled with NumPy 2.0.
Some module may need to rebuild instead e.g. with 'pybind11>=2.12'.

If you are a user of the module, the easiest solution will be to
downgrade to 'numpy<2' or try to upgrade the affected module.
We expect that some modules will need time to support NumPy 2.

Traceback (most recent call last):  File "<frozen runpy>", line 198, in _run_module_as_main
  File "<frozen runpy>", line 88, in _run_code
  File "/home/maciej/anaconda3/lib/python3.12/site-packages/ipykernel_launcher.py", line 17, in <module>
    app.launch_new_instance()
  File "/home/maciej/anaconda3/lib/python3.12/site-packages/traitlets/config/application.py", line 1075, in launch_instance
    app.start()
  File "/home/maciej/anaconda3/lib/python3.12/site-packages/ipykernel/kernelapp.py", line 701, in start
    self.io_loop.start()
  File "/home/maciej/anaconda3/lib/python3.12/site-packages/tornado/platform/asyncio.py", line 205, in start
    self.asyncio_loop.run_forever()
  File "/home/maciej/anaconda3/lib/python3.12/asyncio/base_events.py", line 639, in run_forever
    self._run_once()
  File "/home/maciej/anaconda3/lib/python3.12/asyncio/base_events.py", line 1985, in _run_once
    handle._run()
  File "/home/maciej/anaconda3/lib/python3.12/asyncio/events.py", line 88, in _run
    self._context.run(self._callback, *self._args)
  File "/home/maciej/anaconda3/lib/python3.12/site-packages/ipykernel/kernelbase.py", line 534, in dispatch_queue
    await self.process_one()
  File "/home/maciej/anaconda3/lib/python3.12/site-packages/ipykernel/kernelbase.py", line 523, in process_one
    await dispatch(*args)
  File "/home/maciej/anaconda3/lib/python3.12/site-packages/ipykernel/kernelbase.py", line 429, in dispatch_shell
    await result
  File "/home/maciej/anaconda3/lib/python3.12/site-packages/ipykernel/kernelbase.py", line 767, in execute_request
    reply_content = await reply_content
  File "/home/maciej/anaconda3/lib/python3.12/site-packages/ipykernel/ipkernel.py", line 429, in do_execute
    res = shell.run_cell(
  File "/home/maciej/anaconda3/lib/python3.12/site-packages/ipykernel/zmqshell.py", line 549, in run_cell
    return super().run_cell(*args, **kwargs)
  File "/home/maciej/anaconda3/lib/python3.12/site-packages/IPython/core/interactiveshell.py", line 3075, in run_cell
    result = self._run_cell(
  File "/home/maciej/anaconda3/lib/python3.12/site-packages/IPython/core/interactiveshell.py", line 3130, in _run_cell
    result = runner(coro)
  File "/home/maciej/anaconda3/lib/python3.12/site-packages/IPython/core/async_helpers.py", line 128, in _pseudo_sync_runner
    coro.send(None)
  File "/home/maciej/anaconda3/lib/python3.12/site-packages/IPython/core/interactiveshell.py", line 3334, in run_cell_async
    has_raised = await self.run_ast_nodes(code_ast.body, cell_name,
  File "/home/maciej/anaconda3/lib/python3.12/site-packages/IPython/core/interactiveshell.py", line 3517, in run_ast_nodes
    if await self.run_code(code, result, async_=asy):
  File "/home/maciej/anaconda3/lib/python3.12/site-packages/IPython/core/interactiveshell.py", line 3577, in run_code
    exec(code_obj, self.user_global_ns, self.user_ns)
  File "/tmp/ipykernel_15406/4255111116.py", line 4, in <module>
    import pandas as pd
  File "/home/maciej/anaconda3/lib/python3.12/site-packages/pandas/__init__.py", line 49, in <module>
    from pandas.core.api import (
  File "/home/maciej/anaconda3/lib/python3.12/site-packages/pandas/core/api.py", line 28, in <module>
    from pandas.core.arrays import Categorical
  File "/home/maciej/anaconda3/lib/python3.12/site-packages/pandas/core/arrays/__init__.py", line 1, in <module>
    from pandas.core.arrays.arrow import ArrowExtensionArray
  File "/home/maciej/anaconda3/lib/python3.12/site-packages/pandas/core/arrays/arrow/__init__.py", line 5, in <module>
    from pandas.core.arrays.arrow.array import ArrowExtensionArray
  File "/home/maciej/anaconda3/lib/python3.12/site-packages/pandas/core/arrays/arrow/array.py", line 67, in <module>
    from pandas.core.arrays.masked import BaseMaskedArray
  File "/home/maciej/anaconda3/lib/python3.12/site-packages/pandas/core/arrays/masked.py", line 61, in <module>
    from pandas.core import (
  File "/home/maciej/anaconda3/lib/python3.12/site-packages/pandas/core/nanops.py", line 52, in <module>
    bn = import_optional_dependency("bottleneck", errors="warn")
  File "/home/maciej/anaconda3/lib/python3.12/site-packages/pandas/compat/_optional.py", line 135, in import_optional_dependency
    module = importlib.import_module(name)
  File "/home/maciej/anaconda3/lib/python3.12/importlib/__init__.py", line 90, in import_module
    return _bootstrap._gcd_import(name[level:], package, level)
  File "/home/maciej/anaconda3/lib/python3.12/site-packages/bottleneck/__init__.py", line 7, in <module>
    from .move import (move_argmax, move_argmin, move_max, move_mean, move_median,
------------------

[0;31m---------------------------------------------------------------------------[0m
[0;31mModuleNotFoundError[0m                       Traceback (most recent call last)
Cell [0;32mIn[1], line 5[0m
[1;32m      3[0m [38;5;28;01mimport[39;00m [38;5;21;01mnumpy[39;00m [38;5;28;01mas[39;00m [38;5;21;01mnp[39;00m
[1;32m      4[0m [38;5;28;01mimport[39;00m [38;5;21;01mpandas[39;00m [38;5;28;01mas[39;00m [38;5;21;01mpd[39;00m
[0;32m----> 5[0m [38;5;28;01mimport[39;00m [38;5;21;01mtensorflow[39;00m [38;5;28;01mas[39;00m [38;5;21;01mtf[39;00m
[1;32m      6[0m [38;5;28;01mfrom[39;00m [38;5;21;01mtensorflow[39;00m[38;5;21;01m.[39;00m[38;5;21;01mkeras[39;00m[38;5;21;01m.[39;00m[38;5;21;01mmodels[39;00m [38;5;28;01mimport[39;00m Sequential
[1;32m      7[0m [38;5;28;01mfrom[39;00m [38;5;21;01mtensorflow[39;00m[38;5;21;01m.[39;00m[38;5;21;01mkeras[39;00m[38;5;21;01m.[39;00m[38;5;21;01mlayers[39;00m [38;5;28;01mimport[39;00m SimpleRNN, Dense

[0;31mModuleNotFoundError[0m: No module named 'tensorflow'

