Traceback (most recent call last):
  File "/home/maciej/anaconda3/lib/python3.12/site-packages/jupyter_cache/executors/utils.py", line 58, in single_nb_execution
    executenb(
  File "/home/maciej/anaconda3/lib/python3.12/site-packages/nbclient/client.py", line 1305, in execute
    return NotebookClient(nb=nb, resources=resources, km=km, **kwargs).execute()
           ^^^^^^^^^^^^^^^^^^^^^^^^^^^^^^^^^^^^^^^^^^^^^^^^^^^^^^^^^^^^^^^^^^^^^
  File "/home/maciej/anaconda3/lib/python3.12/site-packages/jupyter_core/utils/__init__.py", line 165, in wrapped
    return loop.run_until_complete(inner)
           ^^^^^^^^^^^^^^^^^^^^^^^^^^^^^^
  File "/home/maciej/anaconda3/lib/python3.12/asyncio/base_events.py", line 685, in run_until_complete
    return future.result()
           ^^^^^^^^^^^^^^^
  File "/home/maciej/anaconda3/lib/python3.12/site-packages/nbclient/client.py", line 705, in async_execute
    await self.async_execute_cell(
  File "/home/maciej/anaconda3/lib/python3.12/site-packages/nbclient/client.py", line 1058, in async_execute_cell
    await self._check_raise_for_error(cell, cell_index, exec_reply)
  File "/home/maciej/anaconda3/lib/python3.12/site-packages/nbclient/client.py", line 914, in _check_raise_for_error
    raise CellExecutionError.from_cell_and_msg(cell, exec_reply_content)
nbclient.exceptions.CellExecutionError: An error occurred while executing the following cell:
------------------
import xgboost as xgb
from sklearn.model_selection import train_test_split
from sklearn.metrics import accuracy_score
import numpy as np

# PrzykÅ‚adowe dane
X = np.array([[1, 2], [2, 3], [3, 4], [4, 5], [5, 6]])
y = np.array([0, 0, 1, 1, 1])

# PodziaÅ‚ danych na zbiÃ³r treningowy i testowy
X_train, X_test, y_train, y_test = train_test_split(X, y, test_size=0.4, random_state=42)

# Utworzenie modelu XGBoost
model = xgb.XGBClassifier(use_label_encoder=False, eval_metric='logloss')

# Trenowanie modelu
model.fit(X_train, y_train)

# Przewidywanie
y_pred = model.predict(X_test)

print(y_pred, y_test)

# Ocena modelu
accuracy = accuracy_score(y_test, y_pred)
print(f'Accuracy: {accuracy}')

------------------


[0;31m---------------------------------------------------------------------------[0m
[0;31mModuleNotFoundError[0m                       Traceback (most recent call last)
Cell [0;32mIn[5], line 1[0m
[0;32m----> 1[0m [38;5;28;01mimport[39;00m [38;5;21;01mxgboost[39;00m [38;5;28;01mas[39;00m [38;5;21;01mxgb[39;00m
[1;32m      2[0m [38;5;28;01mfrom[39;00m [38;5;21;01msklearn[39;00m[38;5;21;01m.[39;00m[38;5;21;01mmodel_selection[39;00m [38;5;28;01mimport[39;00m train_test_split
[1;32m      3[0m [38;5;28;01mfrom[39;00m [38;5;21;01msklearn[39;00m[38;5;21;01m.[39;00m[38;5;21;01mmetrics[39;00m [38;5;28;01mimport[39;00m accuracy_score

[0;31mModuleNotFoundError[0m: No module named 'xgboost'

